<mujoco model="drone">
  <compiler angle="radian" inertiafromgeom="true"/>
  <option integrator="RK4" timestep="0.01"/>
  <worldbody>
    <light diffuse=".5 .5 .5" pos="0 0 3" dir="0 0 -1"/>
    <geom name="ground" type="plane" size="1 1 0.1" rgba=".9 0 0 1"/>
    <body name="drone" pos="0 0 1">
      <joint name="vertical" type="slide" axis="0 0 1"/>
      <geom name="body" type="box" size="0.2 0.2 0.1" rgba="0 0 1 1"/>
      <body name="rotor1" pos="0.2 0 0.05">
        <geom name="rotor1_geom" type="cylinder" size="0.05 0.01" rgba="0 1 0 1"/>
      </body>
      <body name="rotor2" pos="-0.2 0 0.05">
        <geom name="rotor2_geom" type="cylinder" size="0.05 0.01" rgba="0 1 0 1"/>
      </body>
      <body name="rotor3" pos="0 0.2 0.05">
        <geom name="rotor3_geom" type="cylinder" size="0.05 0.01" rgba="0 1 0 1"/>
      </body>
      <body name="rotor4" pos="0 -0.2 0.05">
        <geom name="rotor4_geom" type="cylinder" size="0.05 0.01" rgba="0 1 0 1"/>
      </body>
    </body>
  </worldbody>
  <actuator>
    <motor name="rotor1_motor" joint="vertical" gear="1"/>
    <motor name="rotor2_motor" joint="vertical" gear="1"/>
    <motor name="rotor3_motor" joint="vertical" gear="1"/>
    <motor name="rotor4_motor" joint="vertical" gear="1"/>
  </actuator>
</mujoco>
</mujoco>